Workbook

Sheet Template
C1: Welcome to the Deep Value Hunter Stock Valuation Template!
D2: 1 Static, 2 Load, 3 Refresh | F2: 1 | G2: Static | H2: 2 | I2: Load | J2: 3 | K2: Refresh
C3: Load | E3: This sheet uses the DVH function from the Deep Value Hunter Add-On. Install the Extension from Extensions -> Add-Ons -> Get Add-Ons. Turn Iterative Calculation on in File -> Settings -> Calculation. Enter your ticker in C5 and switch C3 to "Load" to get data on your company! After data is loaded switch C3 to "Static" to lock the sheet. Use "Update" to refresh price data. Get more info at DeepValueHunter.com
C4: =C5
F5: =IFERROR(__xludf.DUMMYFUNCTION("IF($C$3=""Load"",iferror(GOOGLEFINANCE($C$5,""name"")),F5)"),"") | I5: Price Today | R5: Fair Value | S5: IRR | T5: Price ∆ | W5: ROIC (%)
I6: =IFERROR(__xludf.DUMMYFUNCTION("IF($C$3=""Static"", I6, iferror(GOOGLEFINANCE($C$5)))"),"") | Q6: Base Case | R6: =if(S6="No Forecast","",Q63) | S6: =if(countif(G63:H67,"=0")=10,"No Forecast", iferror(Q61,"No Forecast")) -> No Forecast | T6: =if(S6="No Forecast","",R6/I$6-1) | W6: =(F53)/(Q53) -> #VALUE!
Q7: Bear Case | R7: =if(S7="No Forecast","",Q71) | S7: =if(countif(G71:H75,"=0")=10,"No Forecast",iferror(Q69,"No Forecast")) -> No Forecast | T7: =if(S7="No Forecast","",R7/I$6-1)
C8: Last Update | D8: =IF($C$3="Static",D8,today()) -> 46213 | K8: 52 wk H | Q8: Bull Case | R8: =if(S8="No Forecast","",Q79) | S8: =if(countif(G79:H83,"=0")=10,"No Forecast",iferror(Q77,"No Forecast")) -> No Forecast | T8: =if(S8="No Forecast","",R8/I$6-1)
C9: Market cap | D9: =IFERROR(__xludf.DUMMYFUNCTION("IF($C$3=""Static"", D9, iferror(GOOGLEFINANCE($C$5,""marketcap"")))"),"") | K9: =IFERROR(__xludf.DUMMYFUNCTION("IF($C$3=""Load"",iferror(GOOGLEFINANCE($C$5,"""")),F5)"),"")
C10: P/E Ratio | E10: =IFERROR(D9/X53,"") | K10: 52 wk L | Q10: Margin of Safety | R10: 0.15 | S10: 0.2 | T10: 0.3
C11: EV / Operating Income | E11: =iferror(Q53/F53,"") | K11: =IFERROR(__xludf.DUMMYFUNCTION("IF($C$3=""Load"",iferror(GOOGLEFINANCE($C$5,"""")),F5)"),"") | Q11: Target Buy Price | R11: =$R6*(1-R10) -> 0 | S11: =$R6*(1-S10) -> 0 | T11: =$R6*(1-T10) -> 0
C12: Adj FCF Yield | E12: =iferror(K53/P53,"")
C13: Net Debt / Op Income | E13: =N53
C14: Operating Margin | E14: =G53 | L14: Base Case Implied IRR at Different Prices
C15: ROIC | E15: =IF($C$3="Load",if(DVH($C$5,C15)="Data not available",DVH($C$5,C15,2024),DVH($C$5,C15)),E15) -> No data available for | L15: =M15-(N15-M15) -> 0 | M15: =N15-(O15-N15) -> 0 | N15: =O15-(P15-O15) -> 0 | O15: =P15-(Q15-P15) -> 0 | P15: =round(I6,0) -> 0 | Q15: =P15+round($I6/10,0) -> 0 | R15: =Q15+Q15-P15 -> 0 | S15: =R15+R15-Q15 -> 0 | T15: =S15+S15-R15 -> 0
C16: Reporting Currency | E16: USD | L16: =iferror(IRR({-1*$P$53*(L15/$I$6),$I63,$I64,$I65,$I66,$I67+$N65}),"-") -> - | M16: =iferror(IRR({-1*$P$53*(M15/$I$6),$I63,$I64,$I65,$I66,$I67+$N65}),"-") -> - | N16: =iferror(IRR({-1*$P$53*(N15/$I$6),$I63,$I64,$I65,$I66,$I67+$N65}),"-") -> - | O16: =iferror(IRR({-1*$P$53*(O15/$I$6),$I63,$I64,$I65,$I66,$I67+$N65}),"-") -> - | P16: =iferror(IRR({-1*$P$53*(P15/$I$6),$I63,$I64,$I65,$I66,$I67+$N65}),"-") -> - | Q16: =iferror(IRR({-1*$P$53*(Q15/$I$6),$I63,$I64,$I65,$I66,$I67+$N65}),"-") -> - | R16: =iferror(IRR({-1*$P$53*(R15/$I$6),$I63,$I64,$I65,$I66,$I67+$N65}),"-") -> - | S16: =iferror(IRR({-1*$P$53*(S15/$I$6),$I63,$I64,$I65,$I66,$I67+$N65}),"-") -> - | T16: =iferror(IRR({-1*$P$53*(T15/$I$6),$I63,$I64,$I65,$I66,$I67+$N65}),"-") -> -
F20: Bear Case | G20: Base Case | H20: Bull Case
F21: =R7 | G21: =R6 | H21: =R8
F22: =I6 | G22: =I6 | H22: =I6
B32: Reporting Currency | C32: =IF(E16<>"USD", "Historical Data (converted to USD from " & E16 & ")", "Historical Data") -> Historical Data
B33: =E16 -> USD | D33: Revenue ($M) | E33: Y/Y ∆ | F33: Operating Income | G33: Operating Margin | H33: Operating Cash Flow | I33: Capex | J33: SBC | K33: Adj. FCF | L33: Adj. FCF Margin | M33: Net Debt | N33: Net Debt / EBIT | O33: Shares | P33: Market Cap | Q33: EV | R33: Adj. FCF Yield | S33: EV/EBIT | T33: Tangible Book | V33: Gross Profit | W33: Gross Margin | X33: Net Income | Y33: Net Margin | Z33: Op Inc - Net Inc | AA33: Gr Profit - Op Inc | AB33: Rev - Gr Profit
A34: 2007 | B34: {=INDEX('Currency Conversion'!$C$4:$L$23, MATCH(C34, 'Currency Conversion'!$B$4:$B$23, 0), MATCH($E$16, 'Currency Conversion'!$C$3:$L$3, 0))} -> 1 | C34: 2007 | D34: =IF($C$3="Load",DVH($C$5,"revenue",$C34)*$B34,D34) -> #VALUE! | F34: =IF($C$3="Load",DVH($C$5,"operatingincome",$C34)*$B34,F34) -> #VALUE! | G34: =iferror(F34/D34,"") | H34: =IF($C$3="Load",DVH($C$5,"operatingcashflow",$C34)*$B34,H34) -> #VALUE! | I34: =IF($C$3="Load",iferror(DVH($C$5,"capex",$C34)*$B34,""),I34) | J34: =IF($C$3="Load",iferror(DVH($C$5,"sharebasedcompensation",$C34)*$B34,""),J34) | K34: =iferror(H34-I34-J34,"") | L34: =iferror(K34/D34,"") | M34: =IF($C$3="Load",iferror($B34*DVH($C$5,"totaldebt",$C34),"")-iferror($B34*DVH($C$5,"cash",$C34),""),M34) -> 0 | N34: =iferror(M34/F34,"") | O34: =IF($C$3="Load",DVH($C$5,"Shares",$C34),O34) -> No data available for | P34: =IF($C$3="Load",DVH($C$5,"MarketCap",$C34),P34) -> No data available for | Q34: =IF($C$3="Load",DVH($C$5,"EnterpriseValue",$C34),Q34) -> No data available for | R34: =iferror(K34/P34,"") | S34: =iferror(Q34/F34,"") | T34: =IF($C$3="Load",$B34*DVH($C$5,"TangibleBookValue",$C34),T34) -> #VALUE! | V34: =iferror(IF($C$3="Load",DVH($C$5,"grossprofit",$C34)*$B34,V34),"") | W34: =iferror(V34/$D34,"") | X34: =iferror(IF($C$3="Load",DVH($C$5,"netincome",$C34)*$B34,X34),"") | Y34: =iferror(X34/$D34,"") | Z34: =iferror(if(X34<0,if(F34<0,0,F34),if(F34>X34,(F34-X34),0)),"") | AA34: =iferror(if(and(X34<0,F34<0),V34,V34-max(F34,X34)),"") | AB34: =iferror(D34-V34,"")
A35: 2008 | B35: {=INDEX('Currency Conversion'!$C$4:$L$23, MATCH(C35, 'Currency Conversion'!$B$4:$B$23, 0), MATCH($E$16, 'Currency Conversion'!$C$3:$L$3, 0))} -> 1 | C35: 2008 | D35: =IF($C$3="Load",DVH($C$5,"revenue",$C35)*$B35,D35) -> #VALUE! | E35: =iferror(D35/D34-1,"") | F35: =IF($C$3="Load",DVH($C$5,"operatingincome",$C35)*$B35,F35) -> #VALUE! | G35: =iferror(F35/D35,"") | H35: =IF($C$3="Load",DVH($C$5,"operatingcashflow",$C35)*$B35,H35) -> #VALUE! | I35: =IF($C$3="Load",iferror(DVH($C$5,"capex",$C35)*$B35,""),I35) | J35: =IF($C$3="Load",iferror(DVH($C$5,"sharebasedcompensation",$C35)*$B35,""),J35) | K35: =iferror(H35-I35-J35,"") | L35: =iferror(K35/D35,"") | M35: =IF($C$3="Load",iferror($B35*DVH($C$5,"totaldebt",$C35),"")-iferror($B35*DVH($C$5,"cash",$C35),""),M35) -> 0 | N35: =iferror(M35/F35,"") | O35: =IF($C$3="Load",DVH($C$5,"Shares",$C35),O35) -> No data available for | P35: =IF($C$3="Load",DVH($C$5,"MarketCap",$C35),P35) -> No data available for | Q35: =IF($C$3="Load",DVH($C$5,"EnterpriseValue",$C35),Q35) -> No data available for | R35: =iferror(K35/P35,"") | S35: =iferror(Q35/F35,"") | T35: =IF($C$3="Load",$B35*DVH($C$5,"TangibleBookValue",$C35),T35) -> #VALUE! | V35: =iferror(IF($C$3="Load",DVH($C$5,"grossprofit",$C35)*$B35,V35),"") | W35: =iferror(V35/$D35,"") | X35: =iferror(IF($C$3="Load",DVH($C$5,"netincome",$C35)*$B35,X35),"") | Y35: =iferror(X35/$D35,"") | Z35: =iferror(if(X35<0,if(F35<0,0,F35),if(F35>X35,(F35-X35),0)),"") | AA35: =iferror(if(and(X35<0,F35<0),V35,V35-max(F35,X35)),"") | AB35: =iferror(D35-V35,"")
A36: 2009 | B36: {=INDEX('Currency Conversion'!$C$4:$L$23, MATCH(C36, 'Currency Conversion'!$B$4:$B$23, 0), MATCH($E$16, 'Currency Conversion'!$C$3:$L$3, 0))} -> 1 | C36: 2009 | D36: =IF($C$3="Load",DVH($C$5,"revenue",$C36)*$B36,D36) -> #VALUE! | E36: =iferror(D36/D35-1,"") | F36: =IF($C$3="Load",DVH($C$5,"operatingincome",$C36)*$B36,F36) -> #VALUE! | G36: =iferror(F36/D36,"") | H36: =IF($C$3="Load",DVH($C$5,"operatingcashflow",$C36)*$B36,H36) -> #VALUE! | I36: =IF($C$3="Load",iferror(DVH($C$5,"capex",$C36)*$B36,""),I36) | J36: =IF($C$3="Load",iferror(DVH($C$5,"sharebasedcompensation",$C36)*$B36,""),J36) | K36: =iferror(H36-I36-J36,"") | L36: =iferror(K36/D36,"") | M36: =IF($C$3="Load",iferror($B36*DVH($C$5,"totaldebt",$C36),"")-iferror($B36*DVH($C$5,"cash",$C36),""),M36) -> 0 | N36: =iferror(M36/F36,"") | O36: =IF($C$3="Load",DVH($C$5,"Shares",$C36),O36) -> No data available for | P36: =IF($C$3="Load",DVH($C$5,"MarketCap",$C36),P36) -> No data available for | Q36: =IF($C$3="Load",DVH($C$5,"EnterpriseValue",$C36),Q36) -> No data available for | R36: =iferror(K36/P36,"") | S36: =iferror(Q36/F36,"") | T36: =IF($C$3="Load",$B36*DVH($C$5,"TangibleBookValue",$C36),T36) -> #VALUE! | V36: =iferror(IF($C$3="Load",DVH($C$5,"grossprofit",$C36)*$B36,V36),"") | W36: =iferror(V36/$D36,"") | X36: =iferror(IF($C$3="Load",DVH($C$5,"netincome",$C36)*$B36,X36),"") | Y36: =iferror(X36/$D36,"") | Z36: =iferror(if(X36<0,if(F36<0,0,F36),if(F36>X36,(F36-X36),0)),"") | AA36: =iferror(if(and(X36<0,F36<0),V36,V36-max(F36,X36)),"") | AB36: =iferror(D36-V36,"")
A37: 2010 | B37: {=INDEX('Currency Conversion'!$C$4:$L$23, MATCH(C37, 'Currency Conversion'!$B$4:$B$23, 0), MATCH($E$16, 'Currency Conversion'!$C$3:$L$3, 0))} -> 1 | C37: 2010 | D37: =IF($C$3="Load",DVH($C$5,"revenue",$C37)*$B37,D37) -> #VALUE! | E37: =iferror(D37/D36-1,"") | F37: =IF($C$3="Load",DVH($C$5,"operatingincome",$C37)*$B37,F37) -> #VALUE! | G37: =iferror(F37/D37,"") | H37: =IF($C$3="Load",DVH($C$5,"operatingcashflow",$C37)*$B37,H37) -> #VALUE! | I37: =IF($C$3="Load",iferror(DVH($C$5,"capex",$C37)*$B37,""),I37) | J37: =IF($C$3="Load",iferror(DVH($C$5,"sharebasedcompensation",$C37)*$B37,""),J37) | K37: =iferror(H37-I37-J37,"") | L37: =iferror(K37/D37,"") | M37: =IF($C$3="Load",iferror($B37*DVH($C$5,"totaldebt",$C37),"")-iferror($B37*DVH($C$5,"cash",$C37),""),M37) -> 0 | N37: =iferror(M37/F37,"") | O37: =IF($C$3="Load",DVH($C$5,"Shares",$C37),O37) -> No data available for | P37: =IF($C$3="Load",DVH($C$5,"MarketCap",$C37),P37) -> No data available for | Q37: =IF($C$3="Load",DVH($C$5,"EnterpriseValue",$C37),Q37) -> No data available for | R37: =iferror(K37/P37,"") | S37: =iferror(Q37/F37,"") | T37: =IF($C$3="Load",$B37*DVH($C$5,"TangibleBookValue",$C37),T37) -> #VALUE! | V37: =iferror(IF($C$3="Load",DVH($C$5,"grossprofit",$C37)*$B37,V37),"") | W37: =iferror(V37/$D37,"") | X37: =iferror(IF($C$3="Load",DVH($C$5,"netincome",$C37)*$B37,X37),"") | Y37: =iferror(X37/$D37,"") | Z37: =iferror(if(X37<0,if(F37<0,0,F37),if(F37>X37,(F37-X37),0)),"") | AA37: =iferror(if(and(X37<0,F37<0),V37,V37-max(F37,X37)),"") | AB37: =iferror(D37-V37,"")
A38: 2011 | B38: {=INDEX('Currency Conversion'!$C$4:$L$23, MATCH(C38, 'Currency Conversion'!$B$4:$B$23, 0), MATCH($E$16, 'Currency Conversion'!$C$3:$L$3, 0))} -> 1 | C38: 2011 | D38: =IF($C$3="Load",DVH($C$5,"revenue",$C38)*$B38,D38) -> #VALUE! | E38: =iferror(D38/D37-1,"") | F38: =IF($C$3="Load",DVH($C$5,"operatingincome",$C38)*$B38,F38) -> #VALUE! | G38: =iferror(F38/D38,"") | H38: =IF($C$3="Load",DVH($C$5,"operatingcashflow",$C38)*$B38,H38) -> #VALUE! | I38: =IF($C$3="Load",iferror(DVH($C$5,"capex",$C38)*$B38,""),I38) | J38: =IF($C$3="Load",iferror(DVH($C$5,"sharebasedcompensation",$C38)*$B38,""),J38) | K38: =iferror(H38-I38-J38,"") | L38: =iferror(K38/D38,"") | M38: =IF($C$3="Load",iferror($B38*DVH($C$5,"totaldebt",$C38),"")-iferror($B38*DVH($C$5,"cash",$C38),""),M38) -> 0 | N38: =iferror(M38/F38,"") | O38: =IF($C$3="Load",DVH($C$5,"Shares",$C38),O38) -> No data available for | P38: =IF($C$3="Load",DVH($C$5,"MarketCap",$C38),P38) -> No data available for | Q38: =IF($C$3="Load",DVH($C$5,"EnterpriseValue",$C38),Q38) -> No data available for | R38: =iferror(K38/P38,"") | S38: =iferror(Q38/F38,"") | T38: =IF($C$3="Load",$B38*DVH($C$5,"TangibleBookValue",$C38),T38) -> #VALUE! | V38: =iferror(IF($C$3="Load",DVH($C$5,"grossprofit",$C38)*$B38,V38),"") | W38: =iferror(V38/$D38,"") | X38: =iferror(IF($C$3="Load",DVH($C$5,"netincome",$C38)*$B38,X38),"") | Y38: =iferror(X38/$D38,"") | Z38: =iferror(if(X38<0,if(F38<0,0,F38),if(F38>X38,(F38-X38),0)),"") | AA38: =iferror(if(and(X38<0,F38<0),V38,V38-max(F38,X38)),"") | AB38: =iferror(D38-V38,"")
A39: 2012 | B39: {=INDEX('Currency Conversion'!$C$4:$L$23, MATCH(C39, 'Currency Conversion'!$B$4:$B$23, 0), MATCH($E$16, 'Currency Conversion'!$C$3:$L$3, 0))} -> 1 | C39: 2012 | D39: =IF($C$3="Load",DVH($C$5,"revenue",$C39)*$B39,D39) -> #VALUE! | E39: =iferror(D39/D38-1,"") | F39: =IF($C$3="Load",DVH($C$5,"operatingincome",$C39)*$B39,F39) -> #VALUE! | G39: =iferror(F39/D39,"") | H39: =IF($C$3="Load",DVH($C$5,"operatingcashflow",$C39)*$B39,H39) -> #VALUE! | I39: =IF($C$3="Load",iferror(DVH($C$5,"capex",$C39)*$B39,""),I39) | J39: =IF($C$3="Load",iferror(DVH($C$5,"sharebasedcompensation",$C39)*$B39,""),J39) | K39: =iferror(H39-I39-J39,"") | L39: =iferror(K39/D39,"") | M39: =IF($C$3="Load",iferror($B39*DVH($C$5,"totaldebt",$C39),"")-iferror($B39*DVH($C$5,"cash",$C39),""),M39) -> 0 | N39: =iferror(M39/F39,"") | O39: =IF($C$3="Load",DVH($C$5,"Shares",$C39),O39) -> No data available for | P39: =IF($C$3="Load",DVH($C$5,"MarketCap",$C39),P39) -> No data available for | Q39: =IF($C$3="Load",DVH($C$5,"EnterpriseValue",$C39),Q39) -> No data available for | R39: =iferror(K39/P39,"") | S39: =iferror(Q39/F39,"") | T39: =IF($C$3="Load",$B39*DVH($C$5,"TangibleBookValue",$C39),T39) -> #VALUE! | V39: =iferror(IF($C$3="Load",DVH($C$5,"grossprofit",$C39)*$B39,V39),"") | W39: =iferror(V39/$D39,"") | X39: =iferror(IF($C$3="Load",DVH($C$5,"netincome",$C39)*$B39,X39),"") | Y39: =iferror(X39/$D39,"") | Z39: =iferror(if(X39<0,if(F39<0,0,F39),if(F39>X39,(F39-X39),0)),"") | AA39: =iferror(if(and(X39<0,F39<0),V39,V39-max(F39,X39)),"") | AB39: =iferror(D39-V39,"")
A40: 2013 | B40: {=INDEX('Currency Conversion'!$C$4:$L$23, MATCH(C40, 'Currency Conversion'!$B$4:$B$23, 0), MATCH($E$16, 'Currency Conversion'!$C$3:$L$3, 0))} -> 1 | C40: 2013 | D40: =IF($C$3="Load",DVH($C$5,"revenue",$C40)*$B40,D40) -> #VALUE! | E40: =iferror(D40/D39-1,"") | F40: =IF($C$3="Load",DVH($C$5,"operatingincome",$C40)*$B40,F40) -> #VALUE! | G40: =iferror(F40/D40,"") | H40: =IF($C$3="Load",DVH($C$5,"operatingcashflow",$C40)*$B40,H40) -> #VALUE! | I40: =IF($C$3="Load",iferror(DVH($C$5,"capex",$C40)*$B40,""),I40) | J40: =IF($C$3="Load",iferror(DVH($C$5,"sharebasedcompensation",$C40)*$B40,""),J40) | K40: =iferror(H40-I40-J40,"") | L40: =iferror(K40/D40,"") | M40: =IF($C$3="Load",iferror($B40*DVH($C$5,"totaldebt",$C40),"")-iferror($B40*DVH($C$5,"cash",$C40),""),M40) -> 0 | N40: =iferror(M40/F40,"") | O40: =IF($C$3="Load",DVH($C$5,"Shares",$C40),O40) -> No data available for | P40: =IF($C$3="Load",DVH($C$5,"MarketCap",$C40),P40) -> No data available for | Q40: =IF($C$3="Load",DVH($C$5,"EnterpriseValue",$C40),Q40) -> No data available for | R40: =iferror(K40/P40,"") | S40: =iferror(Q40/F40,"") | T40: =IF($C$3="Load",$B40*DVH($C$5,"TangibleBookValue",$C40),T40) -> #VALUE! | V40: =iferror(IF($C$3="Load",DVH($C$5,"grossprofit",$C40)*$B40,V40),"") | W40: =iferror(V40/$D40,"") | X40: =iferror(IF($C$3="Load",DVH($C$5,"netincome",$C40)*$B40,X40),"") | Y40: =iferror(X40/$D40,"") | Z40: =iferror(if(X40<0,if(F40<0,0,F40),if(F40>X40,(F40-X40),0)),"") | AA40: =iferror(if(and(X40<0,F40<0),V40,V40-max(F40,X40)),"") | AB40: =iferror(D40-V40,"")
A41: 2014 | B41: {=INDEX('Currency Conversion'!$C$4:$L$23, MATCH(C41, 'Currency Conversion'!$B$4:$B$23, 0), MATCH($E$16, 'Currency Conversion'!$C$3:$L$3, 0))} -> 1 | C41: 2014 | D41: =IF($C$3="Load",DVH($C$5,"revenue",$C41)*$B41,D41) -> #VALUE! | E41: =iferror(D41/D40-1,"") | F41: =IF($C$3="Load",DVH($C$5,"operatingincome",$C41)*$B41,F41) -> #VALUE! | G41: =iferror(F41/D41,"") | H41: =IF($C$3="Load",DVH($C$5,"operatingcashflow",$C41)*$B41,H41) -> #VALUE! | I41: =IF($C$3="Load",iferror(DVH($C$5,"capex",$C41)*$B41,""),I41) | J41: =IF($C$3="Load",iferror(DVH($C$5,"sharebasedcompensation",$C41)*$B41,""),J41) | K41: =iferror(H41-I41-J41,"") | L41: =iferror(K41/D41,"") | M41: =IF($C$3="Load",iferror($B41*DVH($C$5,"totaldebt",$C41),"")-iferror($B41*DVH($C$5,"cash",$C41),""),M41) -> 0 | N41: =iferror(M41/F41,"") | O41: =IF($C$3="Load",DVH($C$5,"Shares",$C41),O41) -> No data available for | P41: =IF($C$3="Load",DVH($C$5,"MarketCap",$C41),P41) -> No data available for | Q41: =IF($C$3="Load",DVH($C$5,"EnterpriseValue",$C41),Q41) -> No data available for | R41: =iferror(K41/P41,"") | S41: =iferror(Q41/F41,"") | T41: =IF($C$3="Load",$B41*DVH($C$5,"TangibleBookValue",$C41),T41) -> #VALUE! | V41: =iferror(IF($C$3="Load",DVH($C$5,"grossprofit",$C41)*$B41,V41),"") | W41: =iferror(V41/$D41,"") | X41: =iferror(IF($C$3="Load",DVH($C$5,"netincome",$C41)*$B41,X41),"") | Y41: =iferror(X41/$D41,"") | Z41: =iferror(if(X41<0,if(F41<0,0,F41),if(F41>X41,(F41-X41),0)),"") | AA41: =iferror(if(and(X41<0,F41<0),V41,V41-max(F41,X41)),"") | AB41: =iferror(D41-V41,"")
A42: 2015 | B42: {=INDEX('Currency Conversion'!$C$4:$L$23, MATCH(C42, 'Currency Conversion'!$B$4:$B$23, 0), MATCH($E$16, 'Currency Conversion'!$C$3:$L$3, 0))} -> 1 | C42: 2015 | D42: =IF($C$3="Load",DVH($C$5,"revenue",$C42)*$B42,D42) -> #VALUE! | E42: =iferror(D42/D41-1,"") | F42: =IF($C$3="Load",DVH($C$5,"operatingincome",$C42)*$B42,F42) -> #VALUE! | G42: =iferror(F42/D42,"") | H42: =IF($C$3="Load",DVH($C$5,"operatingcashflow",$C42)*$B42,H42) -> #VALUE! | I42: =IF($C$3="Load",iferror(DVH($C$5,"capex",$C42)*$B42,""),I42) | J42: =IF($C$3="Load",iferror(DVH($C$5,"sharebasedcompensation",$C42)*$B42,""),J42) | K42: =iferror(H42-I42-J42,"") | L42: =iferror(K42/D42,"") | M42: =IF($C$3="Load",iferror($B42*DVH($C$5,"totaldebt",$C42),"")-iferror($B42*DVH($C$5,"cash",$C42),""),M42) -> 0 | N42: =iferror(M42/F42,"") | O42: =IF($C$3="Load",DVH($C$5,"Shares",$C42),O42) -> No data available for | P42: =IF($C$3="Load",DVH($C$5,"MarketCap",$C42),P42) -> No data available for | Q42: =IF($C$3="Load",DVH($C$5,"EnterpriseValue",$C42),Q42) -> No data available for | R42: =iferror(K42/P42,"") | S42: =iferror(Q42/F42,"") | T42: =IF($C$3="Load",$B42*DVH($C$5,"TangibleBookValue",$C42),T42) -> #VALUE! | V42: =iferror(IF($C$3="Load",DVH($C$5,"grossprofit",$C42)*$B42,V42),"") | W42: =iferror(V42/$D42,"") | X42: =iferror(IF($C$3="Load",DVH($C$5,"netincome",$C42)*$B42,X42),"") | Y42: =iferror(X42/$D42,"") | Z42: =iferror(if(X42<0,if(F42<0,0,F42),if(F42>X42,(F42-X42),0)),"") | AA42: =iferror(if(and(X42<0,F42<0),V42,V42-max(F42,X42)),"") | AB42: =iferror(D42-V42,"")
A43: 2016 | B43: {=INDEX('Currency Conversion'!$C$4:$L$23, MATCH(C43, 'Currency Conversion'!$B$4:$B$23, 0), MATCH($E$16, 'Currency Conversion'!$C$3:$L$3, 0))} -> 1 | C43: 2016 | D43: =IF($C$3="Load",DVH($C$5,"revenue",$C43)*$B43,D43) -> #VALUE! | E43: =iferror(D43/D42-1,"") | F43: =IF($C$3="Load",DVH($C$5,"operatingincome",$C43)*$B43,F43) -> #VALUE! | G43: =iferror(F43/D43,"") | H43: =IF($C$3="Load",DVH($C$5,"operatingcashflow",$C43)*$B43,H43) -> #VALUE! | I43: =IF($C$3="Load",iferror(DVH($C$5,"capex",$C43)*$B43,""),I43) | J43: =IF($C$3="Load",iferror(DVH($C$5,"sharebasedcompensation",$C43)*$B43,""),J43) | K43: =iferror(H43-I43-J43,"") | L43: =iferror(K43/D43,"") | M43: =IF($C$3="Load",iferror($B43*DVH($C$5,"totaldebt",$C43),"")-iferror($B43*DVH($C$5,"cash",$C43),""),M43) -> 0 | N43: =iferror(M43/F43,"") | O43: =IF($C$3="Load",DVH($C$5,"Shares",$C43),O43) -> No data available for | P43: =IF($C$3="Load",DVH($C$5,"MarketCap",$C43),P43) -> No data available for | Q43: =IF($C$3="Load",DVH($C$5,"EnterpriseValue",$C43),Q43) -> No data available for | R43: =iferror(K43/P43,"") | S43: =iferror(Q43/F43,"") | T43: =IF($C$3="Load",$B43*DVH($C$5,"TangibleBookValue",$C43),T43) -> #VALUE! | V43: =iferror(IF($C$3="Load",DVH($C$5,"grossprofit",$C43)*$B43,V43),"") | W43: =iferror(V43/$D43,"") | X43: =iferror(IF($C$3="Load",DVH($C$5,"netincome",$C43)*$B43,X43),"") | Y43: =iferror(X43/$D43,"") | Z43: =iferror(if(X43<0,if(F43<0,0,F43),if(F43>X43,(F43-X43),0)),"") | AA43: =iferror(if(and(X43<0,F43<0),V43,V43-max(F43,X43)),"") | AB43: =iferror(D43-V43,"")
A44: 2017 | B44: {=INDEX('Currency Conversion'!$C$4:$L$23, MATCH(C44, 'Currency Conversion'!$B$4:$B$23, 0), MATCH($E$16, 'Currency Conversion'!$C$3:$L$3, 0))} -> 1 | C44: 2017 | D44: =IF($C$3="Load",DVH($C$5,"revenue",$C44)*$B44,D44) -> #VALUE! | E44: =iferror(D44/D43-1,"") | F44: =IF($C$3="Load",DVH($C$5,"operatingincome",$C44)*$B44,F44) -> #VALUE! | G44: =iferror(F44/D44,"") | H44: =IF($C$3="Load",DVH($C$5,"operatingcashflow",$C44)*$B44,H44) -> #VALUE! | I44: =IF($C$3="Load",iferror(DVH($C$5,"capex",$C44)*$B44,""),I44) | J44: =IF($C$3="Load",iferror(DVH($C$5,"sharebasedcompensation",$C44)*$B44,""),J44) | K44: =iferror(H44-I44-J44,"") | L44: =iferror(K44/D44,"") | M44: =IF($C$3="Load",iferror($B44*DVH($C$5,"totaldebt",$C44),"")-iferror($B44*DVH($C$5,"cash",$C44),""),M44) -> 0 | N44: =iferror(M44/F44,"") | O44: =IF($C$3="Load",DVH($C$5,"Shares",$C44),O44) -> No data available for | P44: =IF($C$3="Load",DVH($C$5,"MarketCap",$C44),P44) -> No data available for | Q44: =IF($C$3="Load",DVH($C$5,"EnterpriseValue",$C44),Q44) -> No data available for | R44: =iferror(K44/P44,"") | S44: =iferror(Q44/F44,"") | T44: =IF($C$3="Load",$B44*DVH($C$5,"TangibleBookValue",$C44),T44) -> #VALUE! | V44: =iferror(IF($C$3="Load",DVH($C$5,"grossprofit",$C44)*$B44,V44),"") | W44: =iferror(V44/$D44,"") | X44: =iferror(IF($C$3="Load",DVH($C$5,"netincome",$C44)*$B44,X44),"") | Y44: =iferror(X44/$D44,"") | Z44: =iferror(if(X44<0,if(F44<0,0,F44),if(F44>X44,(F44-X44),0)),"") | AA44: =iferror(if(and(X44<0,F44<0),V44,V44-max(F44,X44)),"") | AB44: =iferror(D44-V44,"")
A45: 2018 | B45: {=INDEX('Currency Conversion'!$C$4:$L$23, MATCH(C45, 'Currency Conversion'!$B$4:$B$23, 0), MATCH($E$16, 'Currency Conversion'!$C$3:$L$3, 0))} -> 1 | C45: 2018 | D45: =IF($C$3="Load",DVH($C$5,"revenue",$C45)*$B45,D45) -> #VALUE! | E45: =iferror(D45/D44-1,"") | F45: =IF($C$3="Load",DVH($C$5,"operatingincome",$C45)*$B45,F45) -> #VALUE! | G45: =iferror(F45/D45,"") | H45: =IF($C$3="Load",DVH($C$5,"operatingcashflow",$C45)*$B45,H45) -> #VALUE! | I45: =IF($C$3="Load",iferror(DVH($C$5,"capex",$C45)*$B45,""),I45) | J45: =IF($C$3="Load",iferror(DVH($C$5,"sharebasedcompensation",$C45)*$B45,""),J45) | K45: =iferror(H45-I45-J45,"") | L45: =iferror(K45/D45,"") | M45: =IF($C$3="Load",iferror($B45*DVH($C$5,"totaldebt",$C45),"")-iferror($B45*DVH($C$5,"cash",$C45),""),M45) -> 0 | N45: =iferror(M45/F45,"") | O45: =IF($C$3="Load",DVH($C$5,"Shares",$C45),O45) -> No data available for | P45: =IF($C$3="Load",DVH($C$5,"MarketCap",$C45),P45) -> No data available for | Q45: =IF($C$3="Load",DVH($C$5,"EnterpriseValue",$C45),Q45) -> No data available for | R45: =iferror(K45/P45,"") | S45: =iferror(Q45/F45,"") | T45: =IF($C$3="Load",$B45*DVH($C$5,"TangibleBookValue",$C45),T45) -> #VALUE! | V45: =iferror(IF($C$3="Load",DVH($C$5,"grossprofit",$C45)*$B45,V45),"") | W45: =iferror(V45/$D45,"") | X45: =iferror(IF($C$3="Load",DVH($C$5,"netincome",$C45)*$B45,X45),"") | Y45: =iferror(X45/$D45,"") | Z45: =iferror(if(X45<0,if(F45<0,0,F45),if(F45>X45,(F45-X45),0)),"") | AA45: =iferror(if(and(X45<0,F45<0),V45,V45-max(F45,X45)),"") | AB45: =iferror(D45-V45,"")
A46: 2019 | B46: {=INDEX('Currency Conversion'!$C$4:$L$23, MATCH(C46, 'Currency Conversion'!$B$4:$B$23, 0), MATCH($E$16, 'Currency Conversion'!$C$3:$L$3, 0))} -> 1 | C46: 2019 | D46: =IF($C$3="Load",DVH($C$5,"revenue",$C46)*$B46,D46) -> #VALUE! | E46: =iferror(D46/D45-1,"") | F46: =IF($C$3="Load",DVH($C$5,"operatingincome",$C46)*$B46,F46) -> #VALUE! | G46: =iferror(F46/D46,"") | H46: =IF($C$3="Load",DVH($C$5,"operatingcashflow",$C46)*$B46,H46) -> #VALUE! | I46: =IF($C$3="Load",iferror(DVH($C$5,"capex",$C46)*$B46,""),I46) | J46: =IF($C$3="Load",iferror(DVH($C$5,"sharebasedcompensation",$C46)*$B46,""),J46) | K46: =iferror(H46-I46-J46,"") | L46: =iferror(K46/D46,"") | M46: =IF($C$3="Load",iferror($B46*DVH($C$5,"totaldebt",$C46),"")-iferror($B46*DVH($C$5,"cash",$C46),""),M46) -> 0 | N46: =iferror(M46/F46,"") | O46: =IF($C$3="Load",DVH($C$5,"Shares",$C46),O46) -> No data available for | P46: =IF($C$3="Load",DVH($C$5,"MarketCap",$C46),P46) -> No data available for | Q46: =IF($C$3="Load",DVH($C$5,"EnterpriseValue",$C46),Q46) -> No data available for | R46: =iferror(K46/P46,"") | S46: =iferror(Q46/F46,"") | T46: =IF($C$3="Load",$B46*DVH($C$5,"TangibleBookValue",$C46),T46) -> #VALUE! | V46: =iferror(IF($C$3="Load",DVH($C$5,"grossprofit",$C46)*$B46,V46),"") | W46: =iferror(V46/$D46,"") | X46: =iferror(IF($C$3="Load",DVH($C$5,"netincome",$C46)*$B46,X46),"") | Y46: =iferror(X46/$D46,"") | Z46: =iferror(if(X46<0,if(F46<0,0,F46),if(F46>X46,(F46-X46),0)),"") | AA46: =iferror(if(and(X46<0,F46<0),V46,V46-max(F46,X46)),"") | AB46: =iferror(D46-V46,"")
... A52: 2024 | B52: {=INDEX('Currency Conversion'!$C$4:$L$23, MATCH(C52, 'Currency Conversion'!$B$4:$B$23, 0), MATCH($E$16, 'Currency Conversion'!$C$3:$L$3, 0))} -> 1 | C52: 2025 | D52: =IF($C$3="Load",DVH($C$5,"revenue",$C52)*$B52,D52) -> #VALUE! | E52: =iferror(D52/D51-1,"") | F52: =IF($C$3="Load",DVH($C$5,"operatingincome",$C52)*$B52,F52) -> #VALUE! | G52: =iferror(F52/D52,"") | H52: =IF($C$3="Load",DVH($C$5,"operatingcashflow",$C52)*$B52,H52) -> #VALUE! | I52: =IF($C$3="Load",iferror(DVH($C$5,"capex",$C52)*$B52,""),I52) | J52: =IF($C$3="Load",iferror(DVH($C$5,"sharebasedcompensation",$C52)*$B52,""),J52) | K52: =iferror(H52-I52-J52,"") | L52: =iferror(K52/D52,"") | M52: =IF($C$3="Load",iferror($B52*DVH($C$5,"totaldebt",$C52),"")-iferror($B52*DVH($C$5,"cash",$C52),""),M52) -> 0 | N52: =iferror(M52/F52,"") | O52: =IF($C$3="Load",DVH($C$5,"Shares",$C52),O52) -> No data available for | P52: =IF($C$3="Load",DVH($C$5,"MarketCap",$C52),P52) -> No data available for | Q52: =IF($C$3="Load",DVH($C$5,"EnterpriseValue",$C52),Q52) -> No data available for | R52: =iferror(K52/P52,"") | S52: =iferror(Q52/F52,"") | T52: =IF($C$3="Load",$B52*DVH($C$5,"TangibleBookValue",$C52),T52) -> #VALUE! | V52: =iferror(IF($C$3="Load",DVH($C$5,"grossprofit",$C52)*$B52,V52),"") | W52: =iferror(V52/$D52,"") | X52: =iferror(IF($C$3="Load",DVH($C$5,"netincome",$C52)*$B52,X52),"") | Y52: =iferror(X52/$D52,"") | Z52: =iferror(if(X52<0,if(F52<0,0,F52),if(F52>X52,(F52-X52),0)),"") | AA52: =iferror(if(and(X52<0,F52<0),V52,V52-max(F52,X52)),"") | AB52: =iferror(D52-V52,"")
A53: 2025 | B53: {=INDEX('Currency Conversion'!$C$4:$L$23, MATCH(C53, 'Currency Conversion'!$B$4:$B$23, 0), MATCH($E$16, 'Currency Conversion'!$C$3:$L$3, 0))} -> 1 | C53: TTM | D53: =IF($C$3="Load",DVH($C$5,"revenue",$C53)*$B53,D53) -> #VALUE! | E53: =iferror(D53/D51-1,"") | F53: =IF($C$3="Load",DVH($C$5,"operatingincome",$C53)*$B53,F53) -> #VALUE! | G53: =iferror(F53/D53,"") | H53: =IF($C$3="Load",DVH($C$5,"operatingcashflow",$C53)*$B53,H53) -> #VALUE! | I53: =IF($C$3="Load",iferror(DVH($C$5,"capex",$C53)*$B53,""),I53) | J53: =IF($C$3="Load",iferror(DVH($C$5,"sharebasedcompensation",$C53)*$B53,""),J53) | K53: =iferror(H53-I53-J53,"") | L53: =iferror(K53/D53,"") | M53: =IF($C$3="Load",iferror($B53*DVH($C$5,"totaldebt",$C53),"")-iferror($B53*DVH($C$5,"cash",$C53),""),M53) -> 0 | N53: =iferror(M53/F53,"") | O53: =IFERROR(__xludf.DUMMYFUNCTION("GOOGLEFINANCE($C$5,""shares"")"),"#N/A") -> #N/A | P53: =IFERROR(__xludf.DUMMYFUNCTION("GOOGLEFINANCE($C$5,""marketcap"")"),"#N/A") -> #N/A | Q53: =P53+M53 -> #N/A | R53: =iferror(K53/P53,"") | S53: =iferror(Q53/F53,"") | T53: =IF($C$3="Load",$B53*DVH($C$5,"TangibleBookValue",$C53),T53) -> #VALUE! | V53: =iferror(IF($C$3="Load",DVH($C$5,"grossprofit",$C53)*$B53,V53),"") | W53: =iferror(V53/$D53,"") | X53: =iferror(IF($C$3="Load",DVH($C$5,"netincome",$C53)*$B53,X53),"") | Y53: =iferror(X53/$D53,"") | Z53: =iferror(if(X53<0,if(F53<0,0,F53),if(F53>X53,(F53-X53),0)),"") | AA53: =iferror(if(and(X53<0,F53<0),V53,V53-max(F53,X53)),"") | AB53: =iferror(D53-V53,"") | AC53: =IFERROR(__xludf.DUMMYFUNCTION("IF($C$3=""Load"",GOOGLEFINANCE(C4,""price"",today()-7*365,today(),""weekly""),Arrayformula(AC53:AD449))"),"#N/A") -> #N/A
C54: CAGR or Avg | D54: =iferror((D51/D43)^(1/8)-1,"") | E54: =iferror(AVERAGE(E50:E53),"") | F54: =iferror((F51/F43)^(1/8)-1,"") | G54: =iferror(AVERAGE(G50:G53),"") | H54: =iferror((H51/H43)^(1/8)-1,"") | I54: =iferror((I51/I43)^(1/8)-1,"") | J54: =iferror((J51/J43)^(1/8)-1,"") | K54: =iferror((K51/K43)^(1/8)-1,"") | L54: =iferror(AVERAGE(L50:L53),"") | M54: =iferror((M51/M41)^(1/10)-1,"") | N54: =iferror(AVERAGE(N41:N53),"") | O54: =iferror((O51/O41)^(1/10)-1,"") | P54: =iferror((P51/P41)^(1/10)-1,"") | Q54: =iferror((Q51/Q41)^(1/10)-1,"") | R54: =iferror(TRIMMEAN(R41:R53,0.4),"") | S54: =iferror(TRIMMEAN(S41:S53,0.4),"") | T54: =iferror((T51/T41)^(1/10)-1,"")
D55: =IFERROR(__xludf.DUMMYFUNCTION("sparkline(D43:D53,{""charttype"",""column"";""color"",""0044CC"";""ymin"",min(D43:D53,0);""lastcolor"",""red""})"),"#VALUE!") -> #VALUE! | E55: =IFERROR(__xludf.DUMMYFUNCTION("sparkline(E43:E53,{""charttype"",""column"";""color"",""0044CC"";""ymin"",min(E43:E53,0);""lastcolor"",""red""})"),"#N/A") -> #N/A | F55: =IFERROR(__xludf.DUMMYFUNCTION("sparkline(F43:F53,{""charttype"",""column"";""color"",""0044CC"";""ymin"",min(F43:F53,0);""lastcolor"",""red""})"),"#VALUE!") -> #VALUE! | G55: =IFERROR(__xludf.DUMMYFUNCTION("sparkline(G43:G53,{""charttype"",""column"";""color"",""0044CC"";""ymin"",min(G43:G53,0);""lastcolor"",""red""})"),"#N/A") -> #N/A | H55: =IFERROR(__xludf.DUMMYFUNCTION("sparkline(H43:H53,{""charttype"",""column"";""color"",""0044CC"";""ymin"",min(H43:H53,0);""lastcolor"",""red""})"),"#VALUE!") -> #VALUE! | I55: =IFERROR(__xludf.DUMMYFUNCTION("sparkline(I43:I53,{""charttype"",""column"";""color"",""0044CC"";""ymin"",min(I43:I53,0);""lastcolor"",""red""})"),"#N/A") -> #N/A | J55: =IFERROR(__xludf.DUMMYFUNCTION("sparkline(J43:J53,{""charttype"",""column"";""color"",""0044CC"";""ymin"",min(J43:J53,0);""lastcolor"",""red""})"),"#N/A") -> #N/A | K55: =IFERROR(__xludf.DUMMYFUNCTION("sparkline(K43:K53,{""charttype"",""column"";""color"",""0044CC"";""ymin"",min(K43:K53,0);""lastcolor"",""red""})"),"#N/A") -> #N/A | L55: =IFERROR(__xludf.DUMMYFUNCTION("sparkline(L43:L53,{""charttype"",""column"";""color"",""0044CC"";""ymin"",min(L43:L53,0);""lastcolor"",""red""})"),"#N/A") -> #N/A | M55: =IFERROR(__xludf.DUMMYFUNCTION("sparkline(M43:M53,{""charttype"",""column"";""color"",""0044CC"";""ymin"",min(M43:M53,0);""lastcolor"",""red""})"),"") | N55: =IFERROR(__xludf.DUMMYFUNCTION("sparkline(N43:N53,{""charttype"",""column"";""color"",""0044CC"";""ymin"",min(N43:N53,0);""lastcolor"",""red""})"),"#N/A") -> #N/A | O55: =IFERROR(__xludf.DUMMYFUNCTION("sparkline(O43:O53,{""charttype"",""column"";""color"",""0044CC"";""ymin"",min(O43:O53,0);""lastcolor"",""red""})"),"#N/A") -> #N/A | P55: =IFERROR(__xludf.DUMMYFUNCTION("sparkline(P43:P53,{""charttype"",""column"";""color"",""0044CC"";""ymin"",min(P43:P53,0);""lastcolor"",""red""})"),"#N/A") -> #N/A | Q55: =IFERROR(__xludf.DUMMYFUNCTION("sparkline(Q43:Q53,{""charttype"",""column"";""color"",""0044CC"";""ymin"",min(Q43:Q53,0);""lastcolor"",""red""})"),"#N/A") -> #N/A | R55: =IFERROR(__xludf.DUMMYFUNCTION("sparkline(R43:R53,{""charttype"",""column"";""color"",""0044CC"";""ymin"",min(R43:R53,0);""lastcolor"",""red""})"),"#N/A") -> #N/A | S55: =IFERROR(__xludf.DUMMYFUNCTION("sparkline(S43:S53,{""charttype"",""column"";""color"",""0044CC"";""ymin"",min(S43:S53,0);""lastcolor"",""red""})"),"#N/A") -> #N/A | T55: =IFERROR(__xludf.DUMMYFUNCTION("sparkline(T43:T53,{""charttype"",""column"";""color"",""0044CC"";""ymin"",min(T43:T53,0);""lastcolor"",""red""})"),"#VALUE!") -> #VALUE!
C56: 1
C60: 5-year 2030 Forecasted Data
...

Sheet META
C1: Welcome to the Deep Value Hunter Stock Valuation Template!
C3: Static | E3: This sheet uses the DVH function from the Deep Value Hunter Add-On. Install the Extension from Extensions -> Add-Ons -> Get Add-Ons. Turn Iterative Calculation on in File -> Settings -> Calculation. Enter your ticker in C5 and switch C3 to "Load" to get data on your company! After data is loaded switch C3 to "Static" to lock the sheet. Use "Update" to refresh price data. Get more info at DeepValueHunter.com
C4: =C5 -> META
C5: META | F5: =IFERROR(__xludf.DUMMYFUNCTION("IF($C$3=""Load"",iferror(GOOGLEFINANCE($C$5,""name"")),F5)"),"Meta Platforms Inc") -> Meta Platforms Inc | I5: Price Today | R5: Fair Value | S5: IRR | T5: Price ∆
I6: =IFERROR(__xludf.DUMMYFUNCTION("IF($C$3=""Static"", I6, iferror(GOOGLEFINANCE($C$5)))"),631.48) -> 631.48 | Q6: Base Case | R6: =if(S6="No Forecast","",Q63) -> 1490.0751 | S6: =if(countif(G63:H67,"=0")=10,"No Forecast", iferror(Q61,"No Forecast")) -> 0.34080165 | T6: =if(S6="No Forecast","",R6/I$6-1) -> 1.3596553
Q7: Bear Case | R7: =if(S7="No Forecast","",Q71) | S7: =if(countif(G71:H75,"=0")=10,"No Forecast",iferror(Q69,"No Forecast")) -> No Forecast | T7: =if(S7="No Forecast","",R7/I$6-1)
C8: Last Update | D8: =IF($C$3="Static",D8,today()) -> 46213 | K8: 52 wk H | Q8: Bull Case | R8: =if(S8="No Forecast","",Q79) | S8: =if(countif(G79:H83,"=0")=10,"No Forecast",iferror(Q77,"No Forecast")) -> No Forecast | T8: =if(S8="No Forecast","",R8/I$6-1)
C9: Market cap | D9: =IFERROR(__xludf.DUMMYFUNCTION("IF($C$3=""Static"", D9, iferror(GOOGLEFINANCE($C$5,""marketcap"")))"),1.636079379597E12) -> 1636079379597 | K9: =IFERROR(__xludf.DUMMYFUNCTION("IF($C$3=""Load"",iferror(GOOGLEFINANCE($C$5,"""")),F5)"),"Meta Platforms Inc") -> Meta Platforms Inc
C10: P/E Ratio | E10: =IFERROR(D9/X53,"") -> 27.061421 | K10: 52 wk L | Q10: Margin of Safety | R10: 0.15 | S10: 0.2 | T10: 0.3
C11: EV / Operating Income | E11: =iferror(Q53/F53,"") -> 20.559476 | K11: =IFERROR(__xludf.DUMMYFUNCTION("IF($C$3=""Load"",iferror(GOOGLEFINANCE($C$5,"""")),F5)"),"Meta Platforms Inc") -> Meta Platforms Inc | Q11: Target Buy Price | R11: =$R6*(1-R10) -> 1266.5638 | S11: =$R6*(1-S10) -> 1192.0601 | T11: =$R6*(1-T10) -> 1043.0526
C12: Adj FCF Yield | E12: =iferror(K53/P53,"") -> 0.099191936
C13: Net Debt / Op Income | E13: =N53 -> 0.57668476
C14: Operating Margin | E14: =G53 -> 0.41437855 | L14: Base Case Implied IRR at Different Prices
C15: ROIC | E15: =IF($C$3="Load",if(DVH($C$5,C15)="Data not available",DVH($C$5,C15,2024),DVH($C$5,C15)),E15) -> 0.1795 | L15: =M15-(N15-M15) -> 379 | M15: =N15-(O15-N15) -> 442 | N15: =O15-(P15-O15) -> 505 | O15: =P15-(Q15-P15) -> 568 | P15: =round(I6,0) -> 631 | Q15: =P15+round($I6/10,0) -> 694 | R15: =Q15+Q15-P15 -> 757 | S15: =R15+R15-Q15 -> 820 | T15: =S15+S15-R15 -> 883
C16: Reporting Currency | E16: USD | L16: =iferror(IRR({-1*$P$53*(L15/$I$6),$I63,$I64,$I65,$I66,$I67+$N65}),"-") -> 0.52111142 | M16: =iferror(IRR({-1*$P$53*(M15/$I$6),$I63,$I64,$I65,$I66,$I67+$N65}),"-") -> 0.46308687 | N16: =iferror(IRR({-1*$P$53*(N15/$I$6),$I63,$I64,$I65,$I66,$I67+$N65}),"-") -> 0.41552813 | O16: =iferror(IRR({-1*$P$53*(O15/$I$6),$I63,$I64,$I65,$I66,$I67+$N65}),"-") -> 0.37547746 | P16: =iferror(IRR({-1*$P$53*(P15/$I$6),$I63,$I64,$I65,$I66,$I67+$N65}),"-") -> 0.34104597 | Q16: =iferror(IRR({-1*$P$53*(Q15/$I$6),$I63,$I64,$I65,$I66,$I67+$N65}),"-") -> 0.3109602 | R16: =iferror(IRR({-1*$P$53*(R15/$I$6),$I63,$I64,$I65,$I66,$I67+$N65}),"-") -> 0.28432433 | S16: =iferror(IRR({-1*$P$53*(S15/$I$6),$I63,$I64,$I65,$I66,$I67+$N65}),"-") -> 0.26048627 | T16: =iferror(IRR({-1*$P$53*(T15/$I$6),$I63,$I64,$I65,$I66,$I67+$N65}),"-") -> 0.23895782
F20: Bear Case | G20: Base Case | H20: Bull Case
F21: =R7 | G21: =R6 -> 1490.0751 | H21: =R8
F22: =I6 -> 631.48 | G22: =I6 -> 631.48 | H22: =I6 -> 631.48
B32: Reporting Currency | C32: =IF(E16<>"USD", "Historical Data (converted to USD from " & E16 & ")", "Historical Data") -> Historical Data
B33: =E16 -> USD | D33: Revenue ($M) | E33: Y/Y ∆ | F33: Operating Income | G33: Operating Margin | H33: Operating Cash Flow | I33: Capex | J33: SBC | K33: Adj. FCF | L33: Adj. FCF Margin | M33: Net Debt | N33: Net Debt / EBIT | O33: Shares | P33: Market Cap | Q33: EV | R33: Adj. FCF Yield | S33: EV/EBIT | T33: Tangible Book | V33: Gross Profit | W33: Gross Margin | X33: Net Income | Y33: Net Margin | Z33: Op Inc - Net Inc | AA33: Gr Profit - Op Inc | AB33: Rev - Gr Profit
A34: 2007 | B34: {=INDEX('Currency Conversion'!$C$4:$L$23, MATCH(C34, 'Currency Conversion'!$B$4:$B$23, 0), MATCH($E$16, 'Currency Conversion'!$C$3:$L$3, 0))} -> 1 | C34: 2007 | D34: =IF($C$3="Load",DVH($C$5,"revenue",$C34)*$B34,D34) -> 153000000 | F34: =IF($C$3="Load",DVH($C$5,"operatingincome",$C34)*$B34,F34) -> -124000000 | G34: =iferror(F34/D34,"") -> -0.81045752 | H34: =IF($C$3="Load",DVH($C$5,"operatingcashflow",$C34)*$B34,H34) -> 0 | I34: =IF($C$3="Load",iferror(DVH($C$5,"capex",$C34)*$B34,""),I34) -> 0 | J34: =IF($C$3="Load",iferror(DVH($C$5,"sharebasedcompensation",$C34)*$B34,""),J34) -> 0 | K34: =iferror(H34-I34-J34,"") -> 0 | L34: =iferror(K34/D34,"") -> 0 | M34: =IF($C$3="Load",iferror($B34*DVH($C$5,"totaldebt",$C34),"")-iferror($B34*DVH($C$5,"cash",$C34),""),M34) -> 0 | N34: =iferror(M34/F34,"") -> 0 | O34: =IF($C$3="Load",DVH($C$5,"Shares",$C34),O34) -> 2138085036 | P34: =IF($C$3="Load",DVH($C$5,"MarketCap",$C34),P34) -> 81738990926 | Q34: =IF($C$3="Load",DVH($C$5,"EnterpriseValue",$C34),Q34) -> 0 | R34: =iferror(K34/P34,"") -> 0 | S34: =iferror(Q34/F34,"") -> 0 | T34: =IF($C$3="Load",$B34*DVH($C$5,"TangibleBookValue",$C34),T34) -> 0 | V34: =iferror(IF($C$3="Load",DVH($C$5,"grossprofit",$C34)*$B34,V34),"") -> 112000000 | W34: =iferror(V34/$D34,"") -> 0.73202614 | X34: =iferror(IF($C$3="Load",DVH($C$5,"netincome",$C34)*$B34,X34),"") -> -138000000 | Y34: =iferror(X34/$D34,"") -> -0.90196078 | Z34: =iferror(if(X34<0,if(F34<0,0,F34),if(F34>X34,(F34-X34),0)),"") -> 0 | AA34: =iferror(if(and(X34<0,F34<0),V34,V34-max(F34,X34)),"") -> 112000000 | AB34: =iferror(D34-V34,"") -> 41000000
A35: 2008 | B35: {=INDEX('Currency Conversion'!$C$4:$L$23, MATCH(C35, 'Currency Conversion'!$B$4:$B$23, 0), MATCH($E$16, 'Currency Conversion'!$C$3:$L$3, 0))} -> 1 | C35: 2008 | D35: =IF($C$3="Load",DVH($C$5,"revenue",$C35)*$B35,D35) -> 272000000 | E35: =iferror(D35/D34-1,"") -> 0.77777778 | F35: =IF($C$3="Load",DVH($C$5,"operatingincome",$C35)*$B35,F35) -> -55000000 | G35: =iferror(F35/D35,"") -> -0.20220588 | H35: =IF($C$3="Load",DVH($C$5,"operatingcashflow",$C35)*$B35,H35) -> 0 | I35: =IF($C$3="Load",iferror(DVH($C$5,"capex",$C35)*$B35,""),I35) -> 0 | J35: =IF($C$3="Load",iferror(DVH($C$5,"sharebasedcompensation",$C35)*$B35,""),J35) -> 0 | K35: =iferror(H35-I35-J35,"") -> 0 | L35: =iferror(K35/D35,"") -> 0 | M35: =IF($C$3="Load",iferror($B35*DVH($C$5,"totaldebt",$C35),"")-iferror($B35*DVH($C$5,"cash",$C35),""),M35) -> 0 | N35: =iferror(M35/F35,"") -> 0 | O35: =IF($C$3="Load",DVH($C$5,"Shares",$C35),O35) -> 2138085036 | P35: =IF($C$3="Load",DVH($C$5,"MarketCap",$C35),P35) -> 81738990926 | Q35: =IF($C$3="Load",DVH($C$5,"EnterpriseValue",$C35),Q35) -> 0 | R35: =iferror(K35/P35,"") -> 0 | S35: =iferror(Q35/F35,"") -> 0 | T35: =IF($C$3="Load",$B35*DVH($C$5,"TangibleBookValue",$C35),T35) -> 0 | V35: =iferror(IF($C$3="Load",DVH($C$5,"grossprofit",$C35)*$B35,V35),"") -> 148000000 | W35: =iferror(V35/$D35,"") -> 0.54411765 | X35: =iferror(IF($C$3="Load",DVH($C$5,"netincome",$C35)*$B35,X35),"") -> -56000000 | Y35: =iferror(X35/$D35,"") -> -0.20588235 | Z35: =iferror(if(X35<0,if(F35<0,0,F35),if(F35>X35,(F35-X35),0)),"") -> 0 | AA35: =iferror(if(and(X35<0,F35<0),V35,V35-max(F35,X35)),"") -> 148000000 | AB35: =iferror(D35-V35,"") -> 124000000
A36: 2009 | B36: {=INDEX('Currency Conversion'!$C$4:$L$23, MATCH(C36, 'Currency Conversion'!$B$4:$B$23, 0), MATCH($E$16, 'Currency Conversion'!$C$3:$L$3, 0))} -> 1 | C36: 2009 | D36: =IF($C$3="Load",DVH($C$5,"revenue",$C36)*$B36,D36) -> 777000000 | E36: =iferror(D36/D35-1,"") -> 1.8566176 | F36: =IF($C$3="Load",DVH($C$5,"operatingincome",$C36)*$B36,F36) -> 262000000 | G36: =iferror(F36/D36,"") -> 0.33719434 | H36: =IF($C$3="Load",DVH($C$5,"operatingcashflow",$C36)*$B36,H36) -> 155000000 | I36: =IF($C$3="Load",iferror(DVH($C$5,"capex",$C36)*$B36,""),I36) -> -33000000 | J36: =IF($C$3="Load",iferror(DVH($C$5,"sharebasedcompensation",$C36)*$B36,""),J36) -> 0 | K36: =iferror(H36-I36-J36,"") -> 188000000 | L36: =iferror(K36/D36,"") -> 0.24195624 | M36: =IF($C$3="Load",iferror($B36*DVH($C$5,"totaldebt",$C36),"")-iferror($B36*DVH($C$5,"cash",$C36),""),M36) -> 0 | N36: =iferror(M36/F36,"") -> 0 | O36: =IF($C$3="Load",DVH($C$5,"Shares",$C36),O36) -> 2138085036 | P36: =IF($C$3="Load",DVH($C$5,"MarketCap",$C36),P36) -> 81738990926 | Q36: =IF($C$3="Load",DVH($C$5,"EnterpriseValue",$C36),Q36) -> 0 | R36: =iferror(K36/P36,"") -> 0.0023000039 | S36: =iferror(Q36/F36,"") -> 0 | T36: =IF($C$3="Load",$B36*DVH($C$5,"TangibleBookValue",$C36),T36) -> 0 | V36: =iferror(IF($C$3="Load",DVH($C$5,"grossprofit",$C36)*$B36,V36),"") -> 554000000 | W36: =iferror(V36/$D36,"") -> 0.71299871 | X36: =iferror(IF($C$3="Load",DVH($C$5,"netincome",$C36)*$B36,X36),"") -> 122000000 | Y36: =iferror(X36/$D36,"") -> 0.15701416 | Z36: =iferror(if(X36<0,if(F36<0,0,F36),if(F36>X36,(F36-X36),0)),"") -> 140000000 | AA36: =iferror(if(and(X36<0,F36<0),V36,V36-max(F36,X36)),"") -> 292000000 | AB36: =iferror(D36-V36,"") -> 223000000
A37: 2010 | B37: {=INDEX('Currency Conversion'!$C$4:$L$23, MATCH(C37, 'Currency Conversion'!$B$4:$B$23, 0), MATCH($E$16, 'Currency Conversion'!$C$3:$L$3, 0))} -> 1 | C37: 2010 | D37: =IF($C$3="Load",DVH($C$5,"revenue",$C37)*$B37,D37) -> 1974000000 | E37: =iferror(D37/D36-1,"") -> 1.5405405 | F37: =IF($C$3="Load",DVH($C$5,"operatingincome",$C37)*$B37,F37) -> 1032000000 | G37: =iferror(F37/D37,"") -> 0.52279635 | H37: =IF($C$3="Load",DVH($C$5,"operatingcashflow",$C37)*$B37,H37) -> 698000000 | I37: =IF($C$3="Load",iferror(DVH($C$5,"capex",$C37)*$B37,""),I37) -> -293000000 | J37: =IF($C$3="Load",iferror(DVH($C$5,"sharebasedcompensation",$C37)*$B37,""),J37) -> 20000000 | K37: =iferror(H37-I37-J37,"") -> 971000000 | L37: =iferror(K37/D37,"") -> 0.49189463 | M37: =IF($C$3="Load",iferror($B37*DVH($C$5,"totaldebt",$C37),"")-iferror($B37*DVH($C$5,"cash",$C37),""),M37) -> -1312000000 | N37: =iferror(M37/F37,"") -> -1.2713178 | O37: =IF($C$3="Load",DVH($C$5,"Shares",$C37),O37) -> 2347042528 | P37: =IF($C$3="Load",DVH($C$5,"MarketCap",$C37),P37) -> 87815935845 | Q37: =IF($C$3="Load",DVH($C$5,"EnterpriseValue",$C37),Q37) -> 86503935845 | R37: =iferror(K37/P37,"") -> 0.011057219 | S37: =iferror(Q37/F37,"") -> 83.821643 | T37: =IF($C$3="Load",$B37*DVH($C$5,"TangibleBookValue",$C37),T37) -> 2066000000 | V37: =iferror(IF($C$3="Load",DVH($C$5,"grossprofit",$C37)*$B37,V37),"") -> 1481000000 | W37: =iferror(V37/$D37,"") -> 0.75025329 | X37: =iferror(IF($C$3="Load",DVH($C$5,"netincome",$C37)*$B37,X37),"") -> 372000000 | Y37: =iferror(X37/$D37,"") -> 0.18844985 | Z37: =iferror(if(X37<0,if(F37<0,0,F37),if(F37>X37,(F37-X37),0)),"") -> 660000000 | AA37: =iferror(if(and(X37<0,F37<0),V37,V37-max(F37,X37)),"") -> 449000000 | AB37: =iferror(D37-V37,"") -> 493000000
A38: 2011 | B38: {=INDEX('Currency Conversion'!$C$4:$L$23, MATCH(C38, 'Currency Conversion'!$B$4:$B$23, 0), MATCH($E$16, 'Currency Conversion'!$C$3:$L$3, 0))} -> 1 | C38: 2011 | D38: =IF($C$3="Load",DVH($C$5,"revenue",$C38)*$B38,D38) -> 3711000000 | E38: =iferror(D38/D37-1,"") -> 0.87993921 | F38: =IF($C$3="Load",DVH($C$5,"operatingincome",$C38)*$B38,F38) -> 1756000000 | G38: =iferror(F38/D38,"") -> 0.47318782 | H38: =IF($C$3="Load",DVH($C$5,"operatingcashflow",$C38)*$B38,H38) -> 1549000000 | I38: =IF($C$3="Load",iferror(DVH($C$5,"capex",$C38)*$B38,""),I38) -> -606000000 | J38: =IF($C$3="Load",iferror(DVH($C$5,"sharebasedcompensation",$C38)*$B38,""),J38) -> 217000000 | K38: =iferror(H38-I38-J38,"") -> 1938000000 | L38: =iferror(K38/D38,"") -> 0.5222312 | M38: =IF($C$3="Load",iferror($B38*DVH($C$5,"totaldebt",$C38),"")-iferror($B38*DVH($C$5,"cash",$C38),""),M38) -> -835000000 | N38: =iferror(M38/F38,"") -> -0.47551253 | O38: =IF($C$3="Load",DVH($C$5,"Shares",$C38),O38) -> 2347042529 | P38: =IF($C$3="Load",DVH($C$5,"MarketCap",$C38),P38) -> 87815935845 | Q38: =IF($C$3="Load",DVH($C$5,"EnterpriseValue",$C38),Q38) -> 86980935845 | R38: =iferror(K38/P38,"") -> 0.022068887 | S38: =iferror(Q38/F38,"") -> 49.533563 | T38: =IF($C$3="Load",$B38*DVH($C$5,"TangibleBookValue",$C38),T38) -> 4737000000 | V38: =iferror(IF($C$3="Load",DVH($C$5,"grossprofit",$C38)*$B38,V38),"") -> 2851000000 | W38: =iferror(V38/$D38,"") -> 0.76825653 | X38: =iferror(IF($C$3="Load",DVH($C$5,"netincome",$C38)*$B38,X38),"") -> 1000000000 | Y38: =iferror(X38/$D38,"") -> 0.26946915 | Z38: =iferror(if(X38<0,if(F38<0,0,F38),if(F38>X38,(F38-X38),0)),"") -> 756000000 | AA38: =iferror(if(and(X38<0,F38<0),V38,V38-max(F38,X38)),"") -> 1095000000 | AB38: =iferror(D38-V38,"") -> 860000000
A39: 2012 | B39: {=INDEX('Currency Conversion'!$C$4:$L$23, MATCH(C39, 'Currency Conversion'!$B$4:$B$23, 0), MATCH($E$16, 'Currency Conversion'!$C$3:$L$3, 0))} -> 1 | C39: 2012 | D39: =IF($C$3="Load",DVH($C$5,"revenue",$C39)*$B39,D39) -> 5089000000 | E39: =iferror(D39/D38-1,"") -> 0.37132848 | F39: =IF($C$3="Load",DVH($C$5,"operatingincome",$C39)*$B39,F39) -> 538000000 | G39: =iferror(F39/D39,"") -> 0.10571822 | H39: =IF($C$3="Load",DVH($C$5,"operatingcashflow",$C39)*$B39,H39) -> 1612000000 | I39: =IF($C$3="Load",iferror(DVH($C$5,"capex",$C39)*$B39,""),I39) -> -1235000000 | J39: =IF($C$3="Load",iferror(DVH($C$5,"sharebasedcompensation",$C39)*$B39,""),J39) -> 1572000000 | K39: =iferror(H39-I39-J39,"") -> 1275000000 | L39: =iferror(K39/D39,"") -> 0.25054038 | M39: =IF($C$3="Load",iferror($B39*DVH($C$5,"totaldebt",$C39),"")-iferror($B39*DVH($C$5,"cash",$C39),""),M39) -> -28000000 | N39: =iferror(M39/F39,"") -> -0.05204461 | O39: =IF($C$3="Load",DVH($C$5,"Shares",$C39),O39) -> 3200000000 | P39: =IF($C$3="Load",DVH($C$5,"MarketCap",$C39),P39) -> 85184000000 | Q39: =IF($C$3="Load",DVH($C$5,"EnterpriseValue",$C39),Q39) -> 85156000000 | R39: =iferror(K39/P39,"") -> 0.0149676 | S39: =iferror(Q39/F39,"") -> 158.28253 | T39: =IF($C$3="Load",$B39*DVH($C$5,"TangibleBookValue",$C39),T39) -> 10367000000 | V39: =iferror(IF($C$3="Load",DVH($C$5,"grossprofit",$C39)*$B39,V39),"") -> 3725000000 | W39: =iferror(V39/$D39,"") -> 0.73197092 | X39: =iferror(IF($C$3="Load",DVH($C$5,"netincome",$C39)*$B39,X39),"") -> 53000000 | Y39: =iferror(X39/$D39,"") -> 0.01041462 | Z39: =iferror(if(X39<0,if(F39<0,0,F39),if(F39>X39,(F39-X39),0)),"") -> 485000000 | AA39: =iferror(if(and(X39<0,F39<0),V39,V39-max(F39,X39)),"") -> 3187000000 | AB39: =iferror(D39-V39,"") -> 1364000000
A40: 2013 | B40: {=INDEX('Currency Conversion'!$C$4:$L$23, MATCH(C40, 'Currency Conversion'!$B$4:$B$23, 0), MATCH($E$16, 'Currency Conversion'!$C$3:$L$3, 0))} -> 1 | C40: 2013 | D40: =IF($C$3="Load",DVH($C$5,"revenue",$C40)*$B40,D40) -> 7872000000 | E40: =iferror(D40/D39-1,"") -> 0.54686579 | F40: =IF($C$3="Load",DVH($C$5,"operatingincome",$C40)*$B40,F40) -> 2804000000 | G40: =iferror(F40/D40,"") -> 0.35619919 | H40: =IF($C$3="Load",DVH($C$5,"operatingcashflow",$C40)*$B40,H40) -> 4222000000 | I40: =IF($C$3="Load",iferror(DVH($C$5,"capex",$C40)*$B40,""),I40) -> -1362000000 | J40: =IF($C$3="Load",iferror(DVH($C$5,"sharebasedcompensation",$C40)*$B40,""),J40) -> 906000000 | K40: =iferror(H40-I40-J40,"") -> 4678000000 | L40: =iferror(K40/D40,"") -> 0.59425813 | M40: =IF($C$3="Load",iferror($B40*DVH($C$5,"totaldebt",$C40),"")-iferror($B40*DVH($C$5,"cash",$C40),""),M40) -> -2847000000 | N40: =iferror(M40/F40,"") -> -1.0153352 | O40: =IF($C$3="Load",DVH($C$5,"Shares",$C40),O40) -> 2517000000 | P40: =IF($C$3="Load",DVH($C$5,"MarketCap",$C40),P40) -> 136728853362 | Q40: =IF($C$3="Load",DVH($C$5,"EnterpriseValue",$C40),Q40) -> 133881853362 | R40: =iferror(K40/P40,"") -> 0.0342137 | S40: =iferror(Q40/F40,"") -> 47.746738 | T40: =IF($C$3="Load",$B40*DVH($C$5,"TangibleBookValue",$C40),T40) -> 13748000000 | V40: =iferror(IF($C$3="Load",DVH($C$5,"grossprofit",$C40)*$B40,V40),"") -> 5997000000 | W40: =iferror(V40/$D40,"") -> 0.76181402 | X40: =iferror(IF($C$3="Load",DVH($C$5,"netincome",$C40)*$B40,X40),"") -> 1491000000 | Y40: =iferror(X40/$D40,"") -> 0.18940549 | Z40: =iferror(if(X40<0,if(F40<0,0,F40),if(F40>X40,(F40-X40),0)),"") -> 1313000000 | AA40: =iferror(if(and(X40<0,F40<0),V40,V40-max(F40,X40)),"") -> 3193000000 | AB40: =iferror(D40-V40,"") -> 1875000000
A41: 2014 | B41: {=INDEX('Currency Conversion'!$C$4:$L$23, MATCH(C41, 'Currency Conversion'!$B$4:$B$23, 0), MATCH($E$16, 'Currency Conversion'!$C$3:$L$3, 0))} -> 1 | C41: 2014 | D41: =IF($C$3="Load",DVH($C$5,"revenue",$C41)*$B41,D41) -> 12466000000 | E41: =iferror(D41/D40-1,"") -> 0.5835874 | F41: =IF($C$3="Load",DVH($C$5,"operatingincome",$C41)*$B41,F41) -> 4994000000 | G41: =iferror(F41/D41,"") -> 0.40060966 | H41: =IF($C$3="Load",DVH($C$5,"operatingcashflow",$C41)*$B41,H41) -> 5457000000 | I41: =IF($C$3="Load",iferror(DVH($C$5,"capex",$C41)*$B41,""),I41) -> -1831000000 | J41: =IF($C$3="Load",iferror(DVH($C$5,"sharebasedcompensation",$C41)*$B41,""),J41) -> 1786000000 | K41: =iferror(H41-I41-J41,"") -> 5502000000 | L41: =iferror(K41/D41,"") -> 0.4413605 | M41: =IF($C$3="Load",iferror($B41*DVH($C$5,"totaldebt",$C41),"")-iferror($B41*DVH($C$5,"cash",$C41),""),M41) -> -4082000000 | N41: =iferror(M41/F41,"") -> -0.81738086 | O41: =IF($C$3="Load",DVH($C$5,"Shares",$C41),O41) -> 2664000000 | P41: =IF($C$3="Load",DVH($C$5,"MarketCap",$C41),P41) -> 206784988200 | Q41: =IF($C$3="Load",DVH($C$5,"EnterpriseValue",$C41),Q41) -> 202702988200 | R41: =iferror(K41/P41,"") -> 0.026607347 | S41: =iferror(Q41/F41,"") -> 40.589305 | T41: =IF($C$3="Load",$B41*DVH($C$5,"TangibleBookValue",$C41),T41) -> 14186000000 | V41: =iferror(IF($C$3="Load",DVH($C$5,"grossprofit",$C41)*$B41,V41),"") -> 10313000000 | W41: =iferror(V41/$D41,"") -> 0.82729023 | X41: =iferror(IF($C$3="Load",DVH($C$5,"netincome",$C41)*$B41,X41),"") -> 2940000000 | Y41: =iferror(X41/$D41,"") -> 0.23584149 | Z41: =iferror(if(X41<0,if(F41<0,0,F41),if(F41>X41,(F41-X41),0)),"") -> 2054000000 | AA41: =iferror(if(and(X41<0,F41<0),V41,V41-max(F41,X41)),"") -> 5319000000 | AB41: =iferror(D41-V41,"") -> 2153000000
A42: 2015 | B42: {=INDEX('Currency Conversion'!$C$4:$L$23, MATCH(C42, 'Currency Conversion'!$B$4:$B$23, 0), MATCH($E$16, 'Currency Conversion'!$C$3:$L$3, 0))} -> 1 | C42: 2015 | D42: =IF($C$3="Load",DVH($C$5,"revenue",$C42)*$B42,D42) -> 17928000000 | E42: =iferror(D42/D41-1,"") -> 0.43815177 | F42: =IF($C$3="Load",DVH($C$5,"operatingincome",$C42)*$B42,F42) -> 6225000000 | G42: =iferror(F42/D42,"") -> 0.34722222 | H42: =IF($C$3="Load",DVH($C$5,"operatingcashflow",$C42)*$B42,H42) -> 8599000000 | I42: =IF($C$3="Load",iferror(DVH($C$5,"capex",$C42)*$B42,""),I42) -> -2523000000 | J42: =IF($C$3="Load",iferror(DVH($C$5,"sharebasedcompensation",$C42)*$B42,""),J42) -> 2960000000 | K42: =iferror(H42-I42-J42,"") -> 8162000000 | L42: =iferror(K42/D42,"") -> 0.45526551 | M42: =IF($C$3="Load",iferror($B42*DVH($C$5,"totaldebt",$C42),"")-iferror($B42*DVH($C$5,"cash",$C42),""),M42) -> -4592000000 | N42: =iferror(M42/F42,"") -> -0.73767068 | O42: =IF($C$3="Load",DVH($C$5,"Shares",$C42),O42) -> 2853000000 | P42: =IF($C$3="Load",DVH($C$5,"MarketCap",$C42),P42) -> 297056791980 | Q42: =IF($C$3="Load",DVH($C$5,"EnterpriseValue",$C42),Q42) -> 292464791980 | R42: =iferror(K42/P42,"") -> 0.027476228 | S42: =iferror(Q42/F42,"") -> 46.982296 | T42: =IF($C$3="Load",$B42*DVH($C$5,"TangibleBookValue",$C42),T42) -> 22946000000 | V42: =iferror(IF($C$3="Load",DVH($C$5,"grossprofit",$C42)*$B42,V42),"") -> 15061000000 | W42: =iferror(V42/$D42,"") -> 0.84008255 | X42: =iferror(IF($C$3="Load",DVH($C$5,"netincome",$C42)*$B42,X42),"") -> 3688000000 | Y42: =iferror(X42/$D42,"") -> 0.20571174 | Z42: =iferror(if(X42<0,if(F42<0,0,F42),if(F42>X42,(F42-X42),0)),"") -> 2537000000 | AA42: =iferror(if(and(X42<0,F42<0),V42,V42-max(F42,X42)),"") -> 8836000000 | AB42: =iferror(D42-V42,"") -> 2867000000
A43: 2016 | B43: {=INDEX('Currency Conversion'!$C$4:$L$23, MATCH(C43, 'Currency Conversion'!$B$4:$B$23, 0), MATCH($E$16, 'Currency Conversion'!$C$3:$L$3, 0))} -> 1 | C43: 2016 | D43: =IF($C$3="Load",DVH($C$5,"revenue",$C43)*$B43,D43) -> 27638000000 | E43: =iferror(D43/D42-1,"") -> 0.54161089 | F43: =IF($C$3="Load",DVH($C$5,"operatingincome",$C43)*$B43,F43) -> 12427000000 | G43: =iferror(F43/D43,"") -> 0.44963456 | H43: =IF($C$3="Load",DVH($C$5,"operatingcashflow",$C43)*$B43,H43) -> 16108000000 | I43: =IF($C$3="Load",iferror(DVH($C$5,"capex",$C43)*$B43,""),I43) -> -4491000000 | J43: =IF($C$3="Load",iferror(DVH($C$5,"sharebasedcompensation",$C43)*$B43,""),J43) -> 3218000000 | K43: =iferror(H43-I43-J43,"") -> 17381000000 | L43: =iferror(K43/D43,"") -> 0.62888053 | M43: =IF($C$3="Load",iferror($B43*DVH($C$5,"totaldebt",$C43),"")-iferror($B43*DVH($C$5,"cash",$C43),""),M43) -> -8903000000 | N43: =iferror(M43/F43,"") -> -0.71642392 | O43: =IF($C$3="Load",DVH($C$5,"Shares",$C43),O43) -> 2925000000 | P43: =IF($C$3="Load",DVH($C$5,"MarketCap",$C43),P43) -> 335566104900 | Q43: =IF($C$3="Load",DVH($C$5,"EnterpriseValue",$C43),Q43) -> 326663104900 | R43: =iferror(K43/P43,"") -> 0.051796054 | S43: =iferror(Q43/F43,"") -> 26.286562 | T43: =IF($C$3="Load",$B43*DVH($C$5,"TangibleBookValue",$C43),T43) -> 38537000000 | V43: =iferror(IF($C$3="Load",DVH($C$5,"grossprofit",$C43)*$B43,V43),"") -> 23849000000 | W43: =iferror(V43/$D43,"") -> 0.86290614 | X43: =iferror(IF($C$3="Load",DVH($C$5,"netincome",$C43)*$B43,X43),"") -> 10188000000 | Y43: =iferror(X43/$D43,"") -> 0.36862291 | Z43: =iferror(if(X43<0,if(F43<0,0,F43),if(F43>X43,(F43-X43),0)),"") -> 2239000000 | AA43: =iferror(if(and(X43<0,F43<0),V43,V43-max(F43,X43)),"") -> 11422000000 | AB43: =iferror(D43-V43,"") -> 3789000000
A44: 2017 | B44: {=INDEX('Currency Conversion'!$C$4:$L$23, MATCH(C44, 'Currency Conversion'!$B$4:$B$23, 0), MATCH($E$16, 'Currency Conversion'!$C$3:$L$3, 0))} -> 1 | C44: 2017 | D44: =IF($C$3="Load",DVH($C$5,"revenue",$C44)*$B44,D44) -> 40653000000 | E44: =iferror(D44/D43-1,"") -> 0.47090962 | F44: =IF($C$3="Load",DVH($C$5,"operatingincome",$C44)*$B44,F44) -> 20203000000 | G44: =iferror(F44/D44,"") -> 0.49696209 | H44: =IF($C$3="Load",DVH($C$5,"operatingcashflow",$C44)*$B44,H44) -> 24216000000 | I44: =IF($C$3="Load",iferror(DVH($C$5,"capex",$C44)*$B44,""),I44) -> -6733000000 | J44: =IF($C$3="Load",iferror(DVH($C$5,"sharebasedcompensation",$C44)*$B44,""),J44) -> 3723000000 | K44: =iferror(H44-I44-J44,"") -> 27226000000 | L44: =iferror(K44/D44,"") -> 0.66971687 | M44: =IF($C$3="Load",iferror($B44*DVH($C$5,"totaldebt",$C44),"")-iferror($B44*DVH($C$5,"cash",$C44),""),M44) -> -7739000000 | N44: =iferror(M44/F44,"") -> -0.38306192 | O44: =IF($C$3="Load",DVH($C$5,"Shares",$C44),O44) -> 2956000000 | P44: =IF($C$3="Load",DVH($C$5,"MarketCap",$C44),P44) -> 521157493380 | Q44: =IF($C$3="Load",DVH($C$5,"EnterpriseValue",$C44),Q44) -> 513418493380 | R44: =iferror(K44/P44,"") -> 0.052241406 | S44: =iferror(Q44/F44,"") -> 25.412983 | T44: =IF($C$3="Load",$B44*DVH($C$5,"TangibleBookValue",$C44),T44) -> 54242000000 | V44: =iferror(IF($C$3="Load",DVH($C$5,"grossprofit",$C44)*$B44,V44),"") -> 35199000000 | W44: =iferror(V44/$D44,"") -> 0.86584016 | X44: =iferror(IF($C$3="Load",DVH($C$5,"netincome",$C44)*$B44,X44),"") -> 15920000000 | Y44: =iferror(X44/$D44,"") -> 0.39160702 | Z44: =iferror(if(X44<0,if(F44<0,0,F44),if(F44>X44,(F44-X44),0)),"") -> 4283000000 | AA44: =iferror(if(and(X44<0,F44<0),V44,V44-max(F44,X44)),"") -> 14996000000 | AB44: =iferror(D44-V44,"") -> 5454000000
A45: 2018 | B45: {=INDEX('Currency Conversion'!$C$4:$L$23, MATCH(C45, 'Currency Conversion'!$B$4:$B$23, 0), MATCH($E$16, 'Currency Conversion'!$C$3:$L$3, 0))} -> 1 | C45: 2018 | D45: =IF($C$3="Load",DVH($C$5,"revenue",$C45)*$B45,D45) -> 55838000000 | E45: =iferror(D45/D44-1,"") -> 0.37352717 | F45: =IF($C$3="Load",DVH($C$5,"operatingincome",$C45)*$B45,F45) -> 24913000000 | G45: =iferror(F45/D45,"") -> 0.44616569 | H45: =IF($C$3="Load",DVH($C$5,"operatingcashflow",$C45)*$B45,H45) -> 29274000000 | I45: =IF($C$3="Load",iferror(DVH($C$5,"capex",$C45)*$B45,""),I45) -> -13915000000 | J45: =IF($C$3="Load",iferror(DVH($C$5,"sharebasedcompensation",$C45)*$B45,""),J45) -> 4152000000 | K45: =iferror(H45-I45-J45,"") -> 39037000000 | L45: =iferror(K45/D45,"") -> 0.69911172 | M45: =IF($C$3="Load",iferror($B45*DVH($C$5,"totaldebt",$C45),"")-iferror($B45*DVH($C$5,"cash",$C45),""),M45) -> -9519000000 | N45: =iferror(M45/F45,"") -> -0.38208967 | O45: =IF($C$3="Load",DVH($C$5,"Shares",$C45),O45) -> 2921000000 | P45: =IF($C$3="Load",DVH($C$5,"MarketCap",$C45),P45) -> 378850100000 | Q45: =IF($C$3="Load",DVH($C$5,"EnterpriseValue",$C45),Q45) -> 369331100000 | R45: =iferror(K45/P45,"") -> 0.10304075 | S45: =iferror(Q45/F45,"") -> 14.824834 | T45: =IF($C$3="Load",$B45*DVH($C$5,"TangibleBookValue",$C45),T45) -> 64532000000 | V45: =iferror(IF($C$3="Load",DVH($C$5,"grossprofit",$C45)*$B45,V45),"") -> 46483000000 | W45: =iferror(V45/$D45,"") -> 0.83246176 | X45: =iferror(IF($C$3="Load",DVH($C$5,"netincome",$C45)*$B45,X45),"") -> 22112000000 | Y45: =iferror(X45/$D45,"") -> 0.39600272 | Z45: =iferror(if(X45<0,if(F45<0,0,F45),if(F45>X45,(F45-X45),0)),"") -> 2801000000 | AA45: =iferror(if(and(X45<0,F45<0),V45,V45-max(F45,X45)),"") -> 21570000000 | AB45: =iferror(D45-V45,"") -> 9355000000
A46: 2019 | B46: {=INDEX('Currency Conversion'!$C$4:$L$23, MATCH(C46, 'Currency Conversion'!$B$4:$B$23, 0), MATCH($E$16, 'Currency Conversion'!$C$3:$L$3, 0))} -> 1 | C46: 2019 | D46: =IF($C$3="Load",DVH($C$5,"revenue",$C46)*$B46,D46) -> 70697000000 | E46: =iferror(D46/D45-1,"") -> 0.2661091 | F46: =IF($C$3="Load",DVH($C$5,"operatingincome",$C46)*$B46,F46) -> 23986000000 | G46: =iferror(F46/D46,"") -> 0.33927889 | H46: =IF($C$3="Load",DVH($C$5,"operatingcashflow",$C46)*$B46,H46) -> 36314000000 | I46: =IF($C$3="Load",iferror(DVH($C$5,"capex",$C46)*$B46,""),I46) -> -15102000000 | J46: =IF($C$3="Load",iferror(DVH($C$5,"sharebasedcompensation",$C46)*$B46,""),J46) -> 4836000000 | K46: =iferror(H46-I46-J46,"") -> 46580000000 | L46: =iferror(K46/D46,"") -> 0.65886813 | M46: =IF($C$3="Load",iferror($B46*DVH($C$5,"totaldebt",$C46),"")-iferror($B46*DVH($C$5,"cash",$C46),""),M46) -> -8478000000 | N46: =iferror(M46/F46,"") -> -0.35345618 | O46: =IF($C$3="Load",DVH($C$5,"Shares",$C46),O46) -> 2876000000 | P46: =IF($C$3="Load",DVH($C$5,"MarketCap",$C46),P46) -> 585783500000 | Q46: =IF($C$3="Load",DVH($C$5,"EnterpriseValue",$C46),Q46) -> 577305500000 | R46: =iferror(K46/P46,"") -> 0.079517433 | S46: =iferror(Q46/F46,"") -> 24.068436 | T46: =IF($C$3="Load",$B46*DVH($C$5,"TangibleBookValue",$C46),T46) -> 81445000000 | V46: =iferror(IF($C$3="Load",DVH($C$5,"grossprofit",$C46)*$B46,V46),"") -> 57927000000 | W46: =iferror(V46/$D46,"") -> 0.81936999 | X46: =iferror(IF($C$3="Load",DVH($C$5,"netincome",$C46)*$B46,X46),"") -> 18485000000 | Y46: =iferror(X46/$D46,"") -> 0.26146795 | Z46: =iferror(if(X46<0,if(F46<0,0,F46),if(F46>X46,(F46-X46),0)),"") -> 5501000000 | AA46: =iferror(if(and(X46<0,F46<0),V46,V46-max(F46,X46)),"") -> 33941000000 | AB46: =iferror(D46-V46,"") -> 12770000000
